<?xml version="1.0" ?>
<robot name="camara_movil" xmlns:xacro="http://www.ros.org/wiki/xacro">

<xacro:include filename="$(find camara_movil_description)/urdf/materials.xacro" />
<xacro:include filename="$(find camara_movil_description)/urdf/camara_movil.trans" />
<xacro:include filename="$(find camara_movil_description)/urdf/camara_movil.gazebo" />
<link name="base_link">
  <inertial>
    <origin xyz="-0.011436842088571233 1.5012186169488358e-06 0.12659588390377294" rpy="0 0 0"/>
    <mass value="588.3357714913217"/>
    <inertia ixx="13.487101" iyy="33.233797" izz="42.588403" ixy="-0.000143" iyz="-0.000101" ixz="0.000678"/>
  </inertial>
  <visual>
    <origin xyz="0 0 0" rpy="0 0 0"/>
    <geometry>
      <mesh filename="package://camara_movil_description/meshes/base_link.stl" scale="0.001 0.001 0.001"/>
    </geometry>
    <material name="silver"/>
  </visual>
  <collision>
    <origin xyz="0 0 0" rpy="0 0 0"/>
    <geometry>
      <mesh filename="package://camara_movil_description/meshes/base_link.stl" scale="0.001 0.001 0.001"/>
    </geometry>
  </collision>
</link>

<link name="l01_1">
  <inertial>
    <origin xyz="2.812679527064432e-07 0.0006238922367959587 2.7327584889436096e-08" rpy="0 0 0"/>
    <mass value="34.78504903742396"/>
    <inertia ixx="0.175688" iyy="0.296269" izz="0.175688" ixy="0.0" iyz="0.0" ixz="-0.0"/>
  </inertial>
  <visual>
    <origin xyz="-0.338573 0.21 -0.125029" rpy="0 0 0"/>
    <geometry>
      <mesh filename="package://camara_movil_description/meshes/l01_1.stl" scale="0.001 0.001 0.001"/>
    </geometry>
    <material name="silver"/>
  </visual>
  <collision>
    <origin xyz="-0.338573 0.21 -0.125029" rpy="0 0 0"/>
    <geometry>
      <mesh filename="package://camara_movil_description/meshes/l01_1.stl" scale="0.001 0.001 0.001"/>
    </geometry>
  </collision>
</link>

<link name="l03_1">
  <inertial>
    <origin xyz="2.812679526509321e-07 0.0006238922367957089 2.732756593237795e-08" rpy="0 0 0"/>
    <mass value="34.78504903742395"/>
    <inertia ixx="0.175688" iyy="0.296269" izz="0.175688" ixy="0.0" iyz="-0.0" ixz="0.0"/>
  </inertial>
  <visual>
    <origin xyz="0.361427 0.21 -0.125029" rpy="0 0 0"/>
    <geometry>
      <mesh filename="package://camara_movil_description/meshes/l03_1.stl" scale="0.001 0.001 0.001"/>
    </geometry>
    <material name="silver"/>
  </visual>
  <collision>
    <origin xyz="0.361427 0.21 -0.125029" rpy="0 0 0"/>
    <geometry>
      <mesh filename="package://camara_movil_description/meshes/l03_1.stl" scale="0.001 0.001 0.001"/>
    </geometry>
  </collision>
</link>

<link name="l02_1">
  <inertial>
    <origin xyz="2.812679525954209e-07 -0.0006238922367951261 2.73275850004584e-08" rpy="0 0 0"/>
    <mass value="34.78504903742397"/>
    <inertia ixx="0.175688" iyy="0.296269" izz="0.175688" ixy="-0.0" iyz="-0.0" ixz="-0.0"/>
  </inertial>
  <visual>
    <origin xyz="-0.338573 -0.21 -0.125029" rpy="0 0 0"/>
    <geometry>
      <mesh filename="package://camara_movil_description/meshes/l02_1.stl" scale="0.001 0.001 0.001"/>
    </geometry>
    <material name="silver"/>
  </visual>
  <collision>
    <origin xyz="-0.338573 -0.21 -0.125029" rpy="0 0 0"/>
    <geometry>
      <mesh filename="package://camara_movil_description/meshes/l02_1.stl" scale="0.001 0.001 0.001"/>
    </geometry>
  </collision>
</link>

<link name="l04_1">
  <inertial>
    <origin xyz="2.812679525954209e-07 -0.0006238922367951538 2.7327565987889102e-08" rpy="0 0 0"/>
    <mass value="34.78504903742397"/>
    <inertia ixx="0.175688" iyy="0.296269" izz="0.175688" ixy="0.0" iyz="0.0" ixz="0.0"/>
  </inertial>
  <visual>
    <origin xyz="0.361427 -0.21 -0.125029" rpy="0 0 0"/>
    <geometry>
      <mesh filename="package://camara_movil_description/meshes/l04_1.stl" scale="0.001 0.001 0.001"/>
    </geometry>
    <material name="silver"/>
  </visual>
  <collision>
    <origin xyz="0.361427 -0.21 -0.125029" rpy="0 0 0"/>
    <geometry>
      <mesh filename="package://camara_movil_description/meshes/l04_1.stl" scale="0.001 0.001 0.001"/>
    </geometry>
  </collision>
</link>

<link name="l1_1">
  <inertial>
    <origin xyz="2.8126794662623744e-07 1.947930098151865e-05 0.17518976679685583" rpy="0 0 0"/>
    <mass value="72.03249808197829"/>
    <inertia ixx="0.867804" iyy="0.863984" izz="0.307498" ixy="-0.0" iyz="-0.000203" ixz="0.0"/>
  </inertial>
  <visual>
    <origin xyz="0.011427 -0.0 -0.175029" rpy="0 0 0"/>
    <geometry>
      <mesh filename="package://camara_movil_description/meshes/l1_1.stl" scale="0.001 0.001 0.001"/>
    </geometry>
    <material name="silver"/>
  </visual>
  <collision>
    <origin xyz="0.011427 -0.0 -0.175029" rpy="0 0 0"/>
    <geometry>
      <mesh filename="package://camara_movil_description/meshes/l1_1.stl" scale="0.001 0.001 0.001"/>
    </geometry>
  </collision>
</link>

<link name="l2_1">
  <inertial>
    <origin xyz="2.8126794134400446e-07 0.19760361530970827 0.032595348936150736" rpy="0 0 0"/>
    <mass value="44.90659325604421"/>
    <inertia ixx="0.626775" iyy="0.378961" izz="0.351975" ixy="0.0" iyz="-0.091332" ixz="0.0"/>
  </inertial>
  <visual>
    <origin xyz="0.011427 -0.02 -0.495029" rpy="0 0 0"/>
    <geometry>
      <mesh filename="package://camara_movil_description/meshes/l2_1.stl" scale="0.001 0.001 0.001"/>
    </geometry>
    <material name="silver"/>
  </visual>
  <collision>
    <origin xyz="0.011427 -0.02 -0.495029" rpy="0 0 0"/>
    <geometry>
      <mesh filename="package://camara_movil_description/meshes/l2_1.stl" scale="0.001 0.001 0.001"/>
    </geometry>
  </collision>
</link>

<link name="l3_1">
  <inertial>
    <origin xyz="2.8126793094607194e-07 0.0023947375388668757 0.3246782060627731" rpy="0 0 0"/>
    <mass value="15.76912911354063"/>
    <inertia ixx="0.275689" iyy="0.277554" izz="0.019277" ixy="0.0" iyz="-0.003977" ixz="0.0"/>
  </inertial>
  <visual>
    <origin xyz="0.011427 -0.28 -0.605029" rpy="0 0 0"/>
    <geometry>
      <mesh filename="package://camara_movil_description/meshes/l3_1.stl" scale="0.001 0.001 0.001"/>
    </geometry>
    <material name="silver"/>
  </visual>
  <collision>
    <origin xyz="0.011427 -0.28 -0.605029" rpy="0 0 0"/>
    <geometry>
      <mesh filename="package://camara_movil_description/meshes/l3_1.stl" scale="0.001 0.001 0.001"/>
    </geometry>
  </collision>
</link>

<link name="l5_1">
  <inertial>
    <origin xyz="2.8126791493977843e-07 -0.002394737538907059 0.3246782060627609" rpy="0 0 0"/>
    <mass value="15.769129113540673"/>
    <inertia ixx="0.275689" iyy="0.277554" izz="0.019277" ixy="-0.0" iyz="0.003977" ixz="0.0"/>
  </inertial>
  <visual>
    <origin xyz="0.011427 -0.02 -1.145029" rpy="0 0 0"/>
    <geometry>
      <mesh filename="package://camara_movil_description/meshes/l5_1.stl" scale="0.001 0.001 0.001"/>
    </geometry>
    <material name="silver"/>
  </visual>
  <collision>
    <origin xyz="0.011427 -0.02 -1.145029" rpy="0 0 0"/>
    <geometry>
      <mesh filename="package://camara_movil_description/meshes/l5_1.stl" scale="0.001 0.001 0.001"/>
    </geometry>
  </collision>
</link>

<link name="l4_1">
  <inertial>
    <origin xyz="2.8126792714876225e-07 -0.197603615309756 0.03259534893614391" rpy="0 0 0"/>
    <mass value="44.90659325604385"/>
    <inertia ixx="0.626775" iyy="0.378961" izz="0.351975" ixy="-0.0" iyz="0.091332" ixz="0.0"/>
  </inertial>
  <visual>
    <origin xyz="0.011427 -0.28 -1.035029" rpy="0 0 0"/>
    <geometry>
      <mesh filename="package://camara_movil_description/meshes/l4_1.stl" scale="0.001 0.001 0.001"/>
    </geometry>
    <material name="silver"/>
  </visual>
  <collision>
    <origin xyz="0.011427 -0.28 -1.035029" rpy="0 0 0"/>
    <geometry>
      <mesh filename="package://camara_movil_description/meshes/l4_1.stl" scale="0.001 0.001 0.001"/>
    </geometry>
  </collision>
</link>

<link name="l7_1">
  <inertial>
    <origin xyz="0.002659248732124456 0.0020974782046724594 0.10869578686101766" rpy="0 0 0"/>
    <mass value="51.218441413325046"/>
    <inertia ixx="0.655289" iyy="0.646554" izz="0.173279" ixy="0.00096" iyz="0.004874" ixz="0.003136"/>
  </inertial>
  <visual>
    <origin xyz="0.011427 -0.14 -1.775029" rpy="0 0 0"/>
    <geometry>
      <mesh filename="package://camara_movil_description/meshes/l7_1.stl" scale="0.001 0.001 0.001"/>
    </geometry>
    <material name="silver"/>
  </visual>
  <collision>
    <origin xyz="0.011427 -0.14 -1.775029" rpy="0 0 0"/>
    <geometry>
      <mesh filename="package://camara_movil_description/meshes/l7_1.stl" scale="0.001 0.001 0.001"/>
    </geometry>
  </collision>
</link>

<link name="l6_1">
  <inertial>
    <origin xyz="2.812679069132129e-07 0.11584769784683084 0.050463419712759805" rpy="0 0 0"/>
    <mass value="34.55892933493254"/>
    <inertia ixx="0.207811" iyy="0.191468" izz="0.114309" ixy="0.0" iyz="-0.007241" ixz="0.0"/>
  </inertial>
  <visual>
    <origin xyz="0.011427 -0.02 -1.575029" rpy="0 0 0"/>
    <geometry>
      <mesh filename="package://camara_movil_description/meshes/l6_1.stl" scale="0.001 0.001 0.001"/>
    </geometry>
    <material name="silver"/>
  </visual>
  <collision>
    <origin xyz="0.011427 -0.02 -1.575029" rpy="0 0 0"/>
    <geometry>
      <mesh filename="package://camara_movil_description/meshes/l6_1.stl" scale="0.001 0.001 0.001"/>
    </geometry>
  </collision>
</link>

<joint name="q01" type="continuous">
  <origin xyz="0.338573 -0.21 0.125029" rpy="0 0 0"/>
  <parent link="base_link"/>
  <child link="l01_1"/>
  <axis xyz="0.0 -1.0 -0.0"/>
</joint>

<joint name="q03" type="continuous">
  <origin xyz="-0.361427 -0.21 0.125029" rpy="0 0 0"/>
  <parent link="base_link"/>
  <child link="l03_1"/>
  <axis xyz="0.0 -1.0 -0.0"/>
</joint>

<joint name="q02" type="continuous">
  <origin xyz="0.338573 0.21 0.125029" rpy="0 0 0"/>
  <parent link="base_link"/>
  <child link="l02_1"/>
  <axis xyz="-0.0 1.0 0.0"/>
</joint>

<joint name="q04" type="continuous">
  <origin xyz="-0.361427 0.21 0.125029" rpy="0 0 0"/>
  <parent link="base_link"/>
  <child link="l04_1"/>
  <axis xyz="-0.0 1.0 0.0"/>
</joint>

<joint name="q1" type="continuous">
  <origin xyz="-0.011427 0.0 0.175029" rpy="0 0 0"/>
  <parent link="base_link"/>
  <child link="l1_1"/>
  <axis xyz="-0.0 -0.0 1.0"/>
</joint>

<joint name="q2" type="continuous">
  <origin xyz="0.0 0.02 0.32" rpy="0 0 0"/>
  <parent link="l1_1"/>
  <child link="l2_1"/>
  <axis xyz="-0.0 1.0 -0.0"/>
</joint>

<joint name="q3" type="prismatic">
  <origin xyz="0.0 0.26 0.11" rpy="0 0 0"/>
  <parent link="l2_1"/>
  <child link="l3_1"/>
  <axis xyz="-0.0 -0.0 1.0"/>
  <limit upper="0.25" lower="0.0" effort="100" velocity="100"/>
</joint>

<joint name="q5" type="prismatic">
  <origin xyz="0.0 -0.26 0.11" rpy="0 0 0"/>
  <parent link="l4_1"/>
  <child link="l5_1"/>
  <axis xyz="-0.0 -0.0 1.0"/>
  <limit upper="0.25" lower="0.0" effort="100" velocity="100"/>
</joint>

<joint name="q4" type="continuous">
  <origin xyz="0.0 0.0 0.43" rpy="0 0 0"/>
  <parent link="l3_1"/>
  <child link="l4_1"/>
  <axis xyz="0.0 -1.0 -0.0"/>
</joint>

<joint name="q7" type="continuous">
  <origin xyz="0.0 0.12 0.2" rpy="0 0 0"/>
  <parent link="l6_1"/>
  <child link="l7_1"/>
  <axis xyz="-0.0 -0.0 1.0"/>
</joint>

<joint name="q6" type="continuous">
  <origin xyz="0.0 0.0 0.43" rpy="0 0 0"/>
  <parent link="l5_1"/>
  <child link="l6_1"/>
  <axis xyz="-0.0 1.0 0.0"/>
</joint>

</robot>
