<?xml version="1.0" ?>
<!-- =================================================================================== -->
<!-- |    This document was autogenerated by xacro from camara_movil.xacro             | -->
<!-- |    EDITING THIS FILE BY HAND IS NOT RECOMMENDED                                 | -->
<!-- =================================================================================== -->
<robot name="camara_movil" xmlns:xacro="http://www.ros.org/wiki/xacro">
  <material name="silver">
    <color rgba="0.700 0.700 0.700 1.000"/>
  </material>
  <transmission name="q01_tran">
    <type>transmission_interface/SimpleTransmission</type>
    <joint name="q01">
      <hardwareInterface>hardware_interface/EffortJointInterface</hardwareInterface>
    </joint>
    <actuator name="q01_actr">
      <hardwareInterface>hardware_interface/EffortJointInterface</hardwareInterface>
      <mechanicalReduction>1</mechanicalReduction>
    </actuator>
  </transmission>
  <transmission name="q03_tran">
    <type>transmission_interface/SimpleTransmission</type>
    <joint name="q03">
      <hardwareInterface>hardware_interface/EffortJointInterface</hardwareInterface>
    </joint>
    <actuator name="q03_actr">
      <hardwareInterface>hardware_interface/EffortJointInterface</hardwareInterface>
      <mechanicalReduction>1</mechanicalReduction>
    </actuator>
  </transmission>
  <transmission name="q02_tran">
    <type>transmission_interface/SimpleTransmission</type>
    <joint name="q02">
      <hardwareInterface>hardware_interface/EffortJointInterface</hardwareInterface>
    </joint>
    <actuator name="q02_actr">
      <hardwareInterface>hardware_interface/EffortJointInterface</hardwareInterface>
      <mechanicalReduction>1</mechanicalReduction>
    </actuator>
  </transmission>
  <transmission name="q04_tran">
    <type>transmission_interface/SimpleTransmission</type>
    <joint name="q04">
      <hardwareInterface>hardware_interface/EffortJointInterface</hardwareInterface>
    </joint>
    <actuator name="q04_actr">
      <hardwareInterface>hardware_interface/EffortJointInterface</hardwareInterface>
      <mechanicalReduction>1</mechanicalReduction>
    </actuator>
  </transmission>
  <transmission name="q1_tran">
    <type>transmission_interface/SimpleTransmission</type>
    <joint name="q1">
      <hardwareInterface>hardware_interface/EffortJointInterface</hardwareInterface>
    </joint>
    <actuator name="q1_actr">
      <hardwareInterface>hardware_interface/EffortJointInterface</hardwareInterface>
      <mechanicalReduction>1</mechanicalReduction>
    </actuator>
  </transmission>
  <transmission name="q2_tran">
    <type>transmission_interface/SimpleTransmission</type>
    <joint name="q2">
      <hardwareInterface>hardware_interface/EffortJointInterface</hardwareInterface>
    </joint>
    <actuator name="q2_actr">
      <hardwareInterface>hardware_interface/EffortJointInterface</hardwareInterface>
      <mechanicalReduction>1</mechanicalReduction>
    </actuator>
  </transmission>
  <transmission name="q3_tran">
    <type>transmission_interface/SimpleTransmission</type>
    <joint name="q3">
      <hardwareInterface>hardware_interface/EffortJointInterface</hardwareInterface>
    </joint>
    <actuator name="q3_actr">
      <hardwareInterface>hardware_interface/EffortJointInterface</hardwareInterface>
      <mechanicalReduction>1</mechanicalReduction>
    </actuator>
  </transmission>
  <transmission name="q5_tran">
    <type>transmission_interface/SimpleTransmission</type>
    <joint name="q5">
      <hardwareInterface>hardware_interface/EffortJointInterface</hardwareInterface>
    </joint>
    <actuator name="q5_actr">
      <hardwareInterface>hardware_interface/EffortJointInterface</hardwareInterface>
      <mechanicalReduction>1</mechanicalReduction>
    </actuator>
  </transmission>
  <transmission name="q4_tran">
    <type>transmission_interface/SimpleTransmission</type>
    <joint name="q4">
      <hardwareInterface>hardware_interface/EffortJointInterface</hardwareInterface>
    </joint>
    <actuator name="q4_actr">
      <hardwareInterface>hardware_interface/EffortJointInterface</hardwareInterface>
      <mechanicalReduction>1</mechanicalReduction>
    </actuator>
  </transmission>
  <transmission name="q7_tran">
    <type>transmission_interface/SimpleTransmission</type>
    <joint name="q7">
      <hardwareInterface>hardware_interface/EffortJointInterface</hardwareInterface>
    </joint>
    <actuator name="q7_actr">
      <hardwareInterface>hardware_interface/EffortJointInterface</hardwareInterface>
      <mechanicalReduction>1</mechanicalReduction>
    </actuator>
  </transmission>
  <transmission name="q6_tran">
    <type>transmission_interface/SimpleTransmission</type>
    <joint name="q6">
      <hardwareInterface>hardware_interface/EffortJointInterface</hardwareInterface>
    </joint>
    <actuator name="q6_actr">
      <hardwareInterface>hardware_interface/EffortJointInterface</hardwareInterface>
      <mechanicalReduction>1</mechanicalReduction>
    </actuator>
  </transmission>
  <gazebo>
    <plugin filename="libgazebo_ros_control.so" name="control"/>
  </gazebo>
  <gazebo reference="base_link">
    <material>Gazebo/Silver</material>
    <mu1>0.2</mu1>
    <mu2>0.2</mu2>
    <selfCollide>true</selfCollide>
    <gravity>true</gravity>
  </gazebo>
  <gazebo reference="l01_1">
    <material>Gazebo/Silver</material>
    <mu1>0.2</mu1>
    <mu2>0.2</mu2>
    <selfCollide>true</selfCollide>
  </gazebo>
  <gazebo reference="l03_1">
    <material>Gazebo/Silver</material>
    <mu1>0.2</mu1>
    <mu2>0.2</mu2>
    <selfCollide>true</selfCollide>
  </gazebo>
  <gazebo reference="l02_1">
    <material>Gazebo/Silver</material>
    <mu1>0.2</mu1>
    <mu2>0.2</mu2>
    <selfCollide>true</selfCollide>
  </gazebo>
  <gazebo reference="l04_1">
    <material>Gazebo/Silver</material>
    <mu1>0.2</mu1>
    <mu2>0.2</mu2>
    <selfCollide>true</selfCollide>
  </gazebo>
  <gazebo reference="l1_1">
    <material>Gazebo/Silver</material>
    <mu1>0.2</mu1>
    <mu2>0.2</mu2>
    <selfCollide>true</selfCollide>
  </gazebo>
  <gazebo reference="l2_1">
    <material>Gazebo/Silver</material>
    <mu1>0.2</mu1>
    <mu2>0.2</mu2>
    <selfCollide>true</selfCollide>
  </gazebo>
  <gazebo reference="l3_1">
    <material>Gazebo/Silver</material>
    <mu1>0.2</mu1>
    <mu2>0.2</mu2>
    <selfCollide>true</selfCollide>
  </gazebo>
  <gazebo reference="l5_1">
    <material>Gazebo/Silver</material>
    <mu1>0.2</mu1>
    <mu2>0.2</mu2>
    <selfCollide>true</selfCollide>
  </gazebo>
  <gazebo reference="l4_1">
    <material>Gazebo/Silver</material>
    <mu1>0.2</mu1>
    <mu2>0.2</mu2>
    <selfCollide>true</selfCollide>
  </gazebo>
  <gazebo reference="l7_1">
    <material>Gazebo/Silver</material>
    <mu1>0.2</mu1>
    <mu2>0.2</mu2>
    <selfCollide>true</selfCollide>
  </gazebo>
  <gazebo reference="l6_1">
    <material>Gazebo/Silver</material>
    <mu1>0.2</mu1>
    <mu2>0.2</mu2>
    <selfCollide>true</selfCollide>
  </gazebo>
  <link name="base_link">
    <inertial>
      <origin rpy="0 0 0" xyz="-0.011436842088571233 1.5012186169488358e-06 0.12659588390377294"/>
      <mass value="588.3357714913217"/>
      <inertia ixx="13.487101" ixy="-0.000143" ixz="0.000678" iyy="33.233797" iyz="-0.000101" izz="42.588403"/>
    </inertial>
    <visual>
      <origin rpy="0 0 0" xyz="0 0 0"/>
      <geometry>
        <mesh filename="package://camara_movil_description/meshes/base_link.stl" scale="0.001 0.001 0.001"/>
      </geometry>
      <material name="silver"/>
    </visual>
    <collision>
      <origin rpy="0 0 0" xyz="0 0 0"/>
      <geometry>
        <mesh filename="package://camara_movil_description/meshes/base_link.stl" scale="0.001 0.001 0.001"/>
      </geometry>
    </collision>
  </link>
  <link name="l01_1">
    <inertial>
      <origin rpy="0 0 0" xyz="2.812679527064432e-07 0.0006238922367959587 2.7327584889436096e-08"/>
      <mass value="34.78504903742396"/>
      <inertia ixx="0.175688" ixy="0.0" ixz="-0.0" iyy="0.296269" iyz="0.0" izz="0.175688"/>
    </inertial>
    <visual>
      <origin rpy="0 0 0" xyz="-0.338573 0.21 -0.125029"/>
      <geometry>
        <mesh filename="package://camara_movil_description/meshes/l01_1.stl" scale="0.001 0.001 0.001"/>
      </geometry>
      <material name="silver"/>
    </visual>
    <collision>
      <origin rpy="0 0 0" xyz="-0.338573 0.21 -0.125029"/>
      <geometry>
        <mesh filename="package://camara_movil_description/meshes/l01_1.stl" scale="0.001 0.001 0.001"/>
      </geometry>
    </collision>
  </link>
  <link name="l03_1">
    <inertial>
      <origin rpy="0 0 0" xyz="2.812679526509321e-07 0.0006238922367957089 2.732756593237795e-08"/>
      <mass value="34.78504903742395"/>
      <inertia ixx="0.175688" ixy="0.0" ixz="0.0" iyy="0.296269" iyz="-0.0" izz="0.175688"/>
    </inertial>
    <visual>
      <origin rpy="0 0 0" xyz="0.361427 0.21 -0.125029"/>
      <geometry>
        <mesh filename="package://camara_movil_description/meshes/l03_1.stl" scale="0.001 0.001 0.001"/>
      </geometry>
      <material name="silver"/>
    </visual>
    <collision>
      <origin rpy="0 0 0" xyz="0.361427 0.21 -0.125029"/>
      <geometry>
        <mesh filename="package://camara_movil_description/meshes/l03_1.stl" scale="0.001 0.001 0.001"/>
      </geometry>
    </collision>
  </link>
  <link name="l02_1">
    <inertial>
      <origin rpy="0 0 0" xyz="2.812679525954209e-07 -0.0006238922367951261 2.73275850004584e-08"/>
      <mass value="34.78504903742397"/>
      <inertia ixx="0.175688" ixy="-0.0" ixz="-0.0" iyy="0.296269" iyz="-0.0" izz="0.175688"/>
    </inertial>
    <visual>
      <origin rpy="0 0 0" xyz="-0.338573 -0.21 -0.125029"/>
      <geometry>
        <mesh filename="package://camara_movil_description/meshes/l02_1.stl" scale="0.001 0.001 0.001"/>
      </geometry>
      <material name="silver"/>
    </visual>
    <collision>
      <origin rpy="0 0 0" xyz="-0.338573 -0.21 -0.125029"/>
      <geometry>
        <mesh filename="package://camara_movil_description/meshes/l02_1.stl" scale="0.001 0.001 0.001"/>
      </geometry>
    </collision>
  </link>
  <link name="l04_1">
    <inertial>
      <origin rpy="0 0 0" xyz="2.812679525954209e-07 -0.0006238922367951538 2.7327565987889102e-08"/>
      <mass value="34.78504903742397"/>
      <inertia ixx="0.175688" ixy="0.0" ixz="0.0" iyy="0.296269" iyz="0.0" izz="0.175688"/>
    </inertial>
    <visual>
      <origin rpy="0 0 0" xyz="0.361427 -0.21 -0.125029"/>
      <geometry>
        <mesh filename="package://camara_movil_description/meshes/l04_1.stl" scale="0.001 0.001 0.001"/>
      </geometry>
      <material name="silver"/>
    </visual>
    <collision>
      <origin rpy="0 0 0" xyz="0.361427 -0.21 -0.125029"/>
      <geometry>
        <mesh filename="package://camara_movil_description/meshes/l04_1.stl" scale="0.001 0.001 0.001"/>
      </geometry>
    </collision>
  </link>
  <link name="l1_1">
    <inertial>
      <origin rpy="0 0 0" xyz="2.8126794662623744e-07 1.947930098151865e-05 0.17518976679685583"/>
      <mass value="72.03249808197829"/>
      <inertia ixx="0.867804" ixy="-0.0" ixz="0.0" iyy="0.863984" iyz="-0.000203" izz="0.307498"/>
    </inertial>
    <visual>
      <origin rpy="0 0 0" xyz="0.011427 -0.0 -0.175029"/>
      <geometry>
        <mesh filename="package://camara_movil_description/meshes/l1_1.stl" scale="0.001 0.001 0.001"/>
      </geometry>
      <material name="silver"/>
    </visual>
    <collision>
      <origin rpy="0 0 0" xyz="0.011427 -0.0 -0.175029"/>
      <geometry>
        <mesh filename="package://camara_movil_description/meshes/l1_1.stl" scale="0.001 0.001 0.001"/>
      </geometry>
    </collision>
  </link>
  <link name="l2_1">
    <inertial>
      <origin rpy="0 0 0" xyz="2.8126794134400446e-07 0.19760361530970827 0.032595348936150736"/>
      <mass value="44.90659325604421"/>
      <inertia ixx="0.626775" ixy="0.0" ixz="0.0" iyy="0.378961" iyz="-0.091332" izz="0.351975"/>
    </inertial>
    <visual>
      <origin rpy="0 0 0" xyz="0.011427 -0.02 -0.495029"/>
      <geometry>
        <mesh filename="package://camara_movil_description/meshes/l2_1.stl" scale="0.001 0.001 0.001"/>
      </geometry>
      <material name="silver"/>
    </visual>
    <collision>
      <origin rpy="0 0 0" xyz="0.011427 -0.02 -0.495029"/>
      <geometry>
        <mesh filename="package://camara_movil_description/meshes/l2_1.stl" scale="0.001 0.001 0.001"/>
      </geometry>
    </collision>
  </link>
  <link name="l3_1">
    <inertial>
      <origin rpy="0 0 0" xyz="2.8126793094607194e-07 0.0023947375388668757 0.3246782060627731"/>
      <mass value="15.76912911354063"/>
      <inertia ixx="0.275689" ixy="0.0" ixz="0.0" iyy="0.277554" iyz="-0.003977" izz="0.019277"/>
    </inertial>
    <visual>
      <origin rpy="0 0 0" xyz="0.011427 -0.28 -0.605029"/>
      <geometry>
        <mesh filename="package://camara_movil_description/meshes/l3_1.stl" scale="0.001 0.001 0.001"/>
      </geometry>
      <material name="silver"/>
    </visual>
    <collision>
      <origin rpy="0 0 0" xyz="0.011427 -0.28 -0.605029"/>
      <geometry>
        <mesh filename="package://camara_movil_description/meshes/l3_1.stl" scale="0.001 0.001 0.001"/>
      </geometry>
    </collision>
  </link>
  <link name="l5_1">
    <inertial>
      <origin rpy="0 0 0" xyz="2.8126791493977843e-07 -0.002394737538907059 0.3246782060627609"/>
      <mass value="15.769129113540673"/>
      <inertia ixx="0.275689" ixy="-0.0" ixz="0.0" iyy="0.277554" iyz="0.003977" izz="0.019277"/>
    </inertial>
    <visual>
      <origin rpy="0 0 0" xyz="0.011427 -0.02 -1.145029"/>
      <geometry>
        <mesh filename="package://camara_movil_description/meshes/l5_1.stl" scale="0.001 0.001 0.001"/>
      </geometry>
      <material name="silver"/>
    </visual>
    <collision>
      <origin rpy="0 0 0" xyz="0.011427 -0.02 -1.145029"/>
      <geometry>
        <mesh filename="package://camara_movil_description/meshes/l5_1.stl" scale="0.001 0.001 0.001"/>
      </geometry>
    </collision>
  </link>
  <link name="l4_1">
    <inertial>
      <origin rpy="0 0 0" xyz="2.8126792714876225e-07 -0.197603615309756 0.03259534893614391"/>
      <mass value="44.90659325604385"/>
      <inertia ixx="0.626775" ixy="-0.0" ixz="0.0" iyy="0.378961" iyz="0.091332" izz="0.351975"/>
    </inertial>
    <visual>
      <origin rpy="0 0 0" xyz="0.011427 -0.28 -1.035029"/>
      <geometry>
        <mesh filename="package://camara_movil_description/meshes/l4_1.stl" scale="0.001 0.001 0.001"/>
      </geometry>
      <material name="silver"/>
    </visual>
    <collision>
      <origin rpy="0 0 0" xyz="0.011427 -0.28 -1.035029"/>
      <geometry>
        <mesh filename="package://camara_movil_description/meshes/l4_1.stl" scale="0.001 0.001 0.001"/>
      </geometry>
    </collision>
  </link>
  <link name="l7_1">
    <inertial>
      <origin rpy="0 0 0" xyz="0.002659248732124456 0.0020974782046724594 0.10869578686101766"/>
      <mass value="51.218441413325046"/>
      <inertia ixx="0.655289" ixy="0.00096" ixz="0.003136" iyy="0.646554" iyz="0.004874" izz="0.173279"/>
    </inertial>
    <visual>
      <origin rpy="0 0 0" xyz="0.011427 -0.14 -1.775029"/>
      <geometry>
        <mesh filename="package://camara_movil_description/meshes/l7_1.stl" scale="0.001 0.001 0.001"/>
      </geometry>
      <material name="silver"/>
    </visual>
    <collision>
      <origin rpy="0 0 0" xyz="0.011427 -0.14 -1.775029"/>
      <geometry>
        <mesh filename="package://camara_movil_description/meshes/l7_1.stl" scale="0.001 0.001 0.001"/>
      </geometry>
    </collision>
  </link>
  <link name="l6_1">
    <inertial>
      <origin rpy="0 0 0" xyz="2.812679069132129e-07 0.11584769784683084 0.050463419712759805"/>
      <mass value="34.55892933493254"/>
      <inertia ixx="0.207811" ixy="0.0" ixz="0.0" iyy="0.191468" iyz="-0.007241" izz="0.114309"/>
    </inertial>
    <visual>
      <origin rpy="0 0 0" xyz="0.011427 -0.02 -1.575029"/>
      <geometry>
        <mesh filename="package://camara_movil_description/meshes/l6_1.stl" scale="0.001 0.001 0.001"/>
      </geometry>
      <material name="silver"/>
    </visual>
    <collision>
      <origin rpy="0 0 0" xyz="0.011427 -0.02 -1.575029"/>
      <geometry>
        <mesh filename="package://camara_movil_description/meshes/l6_1.stl" scale="0.001 0.001 0.001"/>
      </geometry>
    </collision>
  </link>
  <joint name="q01" type="continuous">
    <origin rpy="0 0 0" xyz="0.338573 -0.21 0.125029"/>
    <parent link="base_link"/>
    <child link="l01_1"/>
    <axis xyz="0.0 -1.0 -0.0"/>
  </joint>
  <joint name="q03" type="continuous">
    <origin rpy="0 0 0" xyz="-0.361427 -0.21 0.125029"/>
    <parent link="base_link"/>
    <child link="l03_1"/>
    <axis xyz="0.0 -1.0 -0.0"/>
  </joint>
  <joint name="q02" type="continuous">
    <origin rpy="0 0 0" xyz="0.338573 0.21 0.125029"/>
    <parent link="base_link"/>
    <child link="l02_1"/>
    <axis xyz="-0.0 1.0 0.0"/>
  </joint>
  <joint name="q04" type="continuous">
    <origin rpy="0 0 0" xyz="-0.361427 0.21 0.125029"/>
    <parent link="base_link"/>
    <child link="l04_1"/>
    <axis xyz="-0.0 1.0 0.0"/>
  </joint>
  <joint name="q1" type="revolute">
    <origin rpy="0 0 0" xyz="-0.011427 0.0 0.175029"/>
    <parent link="base_link"/>
    <child link="l1_1"/>
    <axis xyz="-0.0 -0.0 1.0"/>
    <limit effort="28.0" lower="-6.28318530718" upper="6.28318530718" velocity="3.2"/>
  </joint>
  <joint name="q2" type="revolute">
    <origin rpy="0 0 0" xyz="0.0 0.02 0.32"/>
    <parent link="l1_1"/>
    <child link="l2_1"/>
    <axis xyz="-0.0 1.0 -0.0"/>
    <limit effort="28.0" lower="-6.28318530718" upper="6.28318530718" velocity="3.2"/>
  </joint>
  <joint name="q3" type="prismatic">
    <origin rpy="0 0 0" xyz="0.0 0.26 0.11"/>
    <parent link="l2_1"/>
    <child link="l3_1"/>
    <axis xyz="-0.0 -0.0 1.0"/>
    <limit effort="100" lower="0.0" upper="0.25" velocity="100.0"/>
  </joint>
  <joint name="q5" type="prismatic">
    <origin rpy="0 0 0" xyz="0.0 -0.26 0.11"/>
    <parent link="l4_1"/>
    <child link="l5_1"/>
    <axis xyz="-0.0 -0.0 1.0"/>
    <limit effort="100" lower="0.0" upper="0.25" velocity="100.0"/>
  </joint>
  <joint name="q4" type="revolute">
    <origin rpy="0 0 0" xyz="0.0 0.0 0.43"/>
    <parent link="l3_1"/>
    <child link="l4_1"/>
    <axis xyz="0.0 -1.0 -0.0"/>
    <limit effort="28.0" lower="-6.28318530718" upper="6.28318530718" velocity="3.2"/>
  </joint>
  <joint name="q7" type="revolute">
    <origin rpy="0 0 0" xyz="0.0 0.12 0.2"/>
    <parent link="l6_1"/>
    <child link="l7_1"/>
    <axis xyz="-0.0 -0.0 1.0"/>
    <limit effort="28.0" lower="-6.28318530718" upper="6.28318530718" velocity="3.2"/>
  </joint>
  <joint name="q6" type="revolute">
    <origin rpy="0 0 0" xyz="0.0 0.0 0.43"/>
    <parent link="l5_1"/>
    <child link="l6_1"/>
    <axis xyz="-0.0 1.0 0.0"/>
    <limit effort="28.0" lower="-6.28318530718" upper="6.28318530718" velocity="3.2"/>
  </joint>
</robot>

